Workbook

Sheet 공사정보_출력X
B2: 공사명 | C2: (예시) OO부대 시설물 보수공사
B3: 공사 공종 | C3: 종합공사
B4: 현장소재지 | C4: OO도 OO시 OO구
B5: 착공신고일자 | C5: 46035
B6: 원청사 | C6: 주식회사 가상건설 | D6: 031-000-0000 | E6: OO도 OO시 OO구 OO로 00 (OO동) OOO호
B7: 대표 | C7: 홍길동
B8: 발주처 | C8: OO부대 | D8: 031-000-0001
B9: 계약금액 | C9: 150000000
B10: 계약년월일 | C10: 46029
B11: 착공년월일 | C11: 46029
B12: 준공(예정)년월일 | C12: 46073
B13: 현장대리인 | C13: 홍길동 | D13: 연락처 | E13: 010-1234-5678
D14: 주소 | E14: OO도 OO시 OO구 OO동 000-00
D15: 주민등록번호
D16: 생년월일
C17: 자격증 수첩이면 | D17: 자격번호 | E17: 00000000000X
C18: 자격증 이면 | D18: 관리번호
D19: 면허종류 | E19: 중급
D20: 입사일
B21: 계약번호 | C21: 2026-OO-001

Sheet 공문
A1: =공사정보_출력X!C6 -> 주식회사 가상건설
A3: 문서번호 : 가상건설 - 260107 - 01호 | C3: 선결 | F3: 지시
A4: ="수 신 : "&공사정보_출력X!C8 -> 수 신 : OO부대 | C4: 접 수 | D4: 일자 시간 | F4: 결재 · 공람
D5: 번호
A6: 경 유 : | C6: 처리자
C7: 담당자
A8: ="제 목 : "&공사정보_출력X!C2&" 착공계 제출의 건 " -> 제 목 : (예시) OO부대 시설물 보수공사 착공계 제출의 건
B10: ="1. 귀 "&공사정보_출력X!C8&"의 무궁한 발전을 기원합니다." -> 1. 귀 OO부대의 무궁한 발전을 기원합니다.
B12: ="2. 관련근거 : 계약번호 "&공사정보_출력X!C21&" ("&TEXT(공사정보_출력X!C10,"yyyy. m. d")&")" -> 2. 관련근거 : 계약번호 2026-OO-001 (2026. 1. 7)
B14: 3. 위 관련근거에 의거하여 착공신고서를 제출합니다.
A24: * 붙 임 : 1. 착공신고서 1부. 끝.
A28: =공사정보_출력X!C6&" 대표이사 "&공사정보_출력X!C7 -> 주식회사 가상건설 대표이사 홍길동

Sheet 표지
A6: 착공신고서
A11: =공사정보_출력X!C2 -> (예시) OO부대 시설물 보수공사
A22: =공사정보_출력X!C5 -> 46035
A30: =공사정보_출력X!C6 -> 주식회사 가상건설
A37: =공사정보_출력X!C8 -> OO부대

Sheet 목차
A5: 목차
D9: 1. 착공신고서
D10: 2. 현장대리인 지정신고서
D11: 3. 공정표
D12: 4. 품질관리계획서
D13: 5. 안전관리계획서
D14: 6. 환경보전계획서
D15: 7. 인력 및 장비투입계획서
D16: 8. 착공 전 사진
D17: 9. 도급계약서 사본
D19: 11. 착공전 현장사진
D20: 12. 기타서류

Sheet 1.착공신고서
B1: 1. 착공신고서
B3: 공사명 | C3: : | D3: =공사정보_출력X!C2 -> (예시) OO부대 시설물 보수공사
B4: 공사금액 | C4: : | D4: ="일금 "&numberstring(공사정보_출력X!C9,1)&"원정 ("&DOLLAR(공사정보_출력X!C9,0)&") " -> #NAME?
B5: 계약번호 | C5: : | D5: =공사정보_출력X!C21 -> 2026-OO-001
B6: 계약년월일 | C6: : | D6: =공사정보_출력X!C10 -> 46029
B7: 착공년월일 | C7: : | D7: =공사정보_출력X!C11 -> 46029
B8: 준공(예정)년월일 | C8: : | D8: =공사정보_출력X!C12 -> 46073
B10: 상기와 같이 착공하였기에 착공계를 제출합니다.
B14: 붙임 : | C14: 1. 현장대리인 지정신고서
C15: 2. 공사예정표
C16: 3. 품질관리계획서
C17: 4. 안전관리계획서
C18: 5. 롼경관리계획서
C19: 6. 인력 및 장비 투입계획서
C20: 7. 착공 전 사진
C21: 8. 공사도급계약서 및 산출내역서
B23: =공사정보_출력X!C5 -> 46035
D25: 주소 | E25: : | F25: =공사정보_출력X!E6 -> OO도 OO시 OO구 OO로 00 (OO동) OOO호
D26: 상호 | E26: : | F26: =공사정보_출력X!C6 -> 주식회사 가상건설
D27: 대표 | E27: : | F27: =공사정보_출력X!C7 -> 홍길동 | G27: (인)
B30: =공사정보_출력X!C8 -> OO부대

Sheet 2.현장대리인계
A1: 2. 현장대리인 지정신고서
A3: 공사명 | C3: =공사정보_출력X!C2 -> (예시) OO부대 시설물 보수공사
A4: 공사금액 | C4: =G4 -> 150000000 | G4: =공사정보_출력X!C9 -> 150000000
A5: 계약번호 | C5: =공사정보_출력X!C21 -> 2026-OO-001
A6: 계약년월일 | C6: =공사정보_출력X!C10 -> 46029
A7: 착공년월일 | C7: =공사정보_출력X!C11 -> 46029
A8: 준공예정년월일 | C8: =공사정보_출력X!C12 -> 46073
A10: 현장대리인 | C10: 주소 | D10: : | E10: =공사정보_출력X!E14 -> OO도 OO시 OO구 OO동 000-00
C11: 성명 | D11: : | E11: =공사정보_출력X!C13 -> 홍길동
C12: 생년월일 | D12: : | E12: =공사정보_출력X!E16 -> 0
C13: 기술자격등급 | D13: : | E13: =공사정보_출력X!E19 -> 중급
C14: 면 허 번 호 | D14: : | E14: =공사정보_출력X!E17 -> 00000000000X
A16: 위와 같이 현장대리인기술자로 선정하였기에 제출합니다.
A18: =공사정보_출력X!C5 -> 46035
A19: 붙임 : | B19: 1. 재직증명서 1부.
B20: 2. 건설기술자 경력증명서 1부. 끝.
C23: 주소 | D23: : | E23: =공사정보_출력X!E6 -> OO도 OO시 OO구 OO로 00 (OO동) OOO호
C24: 상호 | D24: : | E24: =공사정보_출력X!C6 -> 주식회사 가상건설
C25: 대표이사 | D25: : | E25: =공사정보_출력X!C7 -> 홍길동 | G25: (인)
A27: 3-2. 안전관리자선임계
A28: 공사명 | C28: =C3 -> (예시) OO부대 시설물 보수공사
A29: 계약금액 | C29: =C4 -> 150000000 | G29: =G4 -> 150000000
A30: 계약년월일 | C30: =C6 -> 46029
A31: 착공년월일 | C31: =C7 -> 46029
A32: 준공예정년월일 | C32: =C8 -> 46073
A34: 안전관리자 | C34: 주소 | D34: : | E34: =E10 -> OO도 OO시 OO구 OO동 000-00
C35: 성명 | D35: : | E35: =E11 -> 홍길동
C36: 생년월일 | D36: : | E36: =E12 -> 0
C37: 면허종목및등급 | D37: : | E37: =E13 -> 중급
C38: 면허번호 | D38: : | E38: =E14 -> 00000000000X
A40: 위와 같이 안전관리자를 선정 위 공사현장에 상주하게 하여 현장감독관의 감독 또는 지시에 따라 우리 회사를 대표하여 공사현장의 단속 및 공사에 관한 모든 사항을 처리하며, 이에 안전관리자선임계를 제출합니다.
A42: =A18 -> 46035
C45: 주소 | D45: : | E45: =E23 -> OO도 OO시 OO구 OO로 00 (OO동) OOO호
C46: 상호 | D46: : | E46: =E24 -> 주식회사 가상건설
C47: 대표이사 | D47: : | E47: =E25 -> 홍길동 | G47: (인)
A51: 3-3. 품질관리자선임계
A52: 공사명 | C52: =C28 -> (예시) OO부대 시설물 보수공사
A53: 계약금액 | C53: =G53 -> 150000000 | G53: =G29 -> 150000000
A54: 계약년월일 | C54: =C30 -> 46029
A55: 착공년월일 | C55: =C31 -> 46029
...

Sheet 3.공정표
A1: 3. 공 사 예 정 공 정 표
A4: 공 사 명 | C4: =공사정보_출력X!C2 -> (예시) OO부대 시설물 보수공사 | M4: 착공일자 : | P4: =공사정보_출력X!C11 -> 46029
M5: 준공일자 : | P5: =공사정보_출력X!C12 -> 46073
A6: 공 종 별 | C6: 11월 | L6: 12월
C7: 7 | D7: =C7+3 -> 10 | E7: =D7+3 -> 13 | F7: =E7+3 -> 16 | G7: =F7+3 -> 19 | H7: =G7+3 -> 22 | I7: =H7+3 -> 25 | J7: =I7+3 -> 28 | K7: =J7+2 -> 30 | L7: 1 | M7: =L7+3 -> 4 | N7: =M7+3 -> 7 | O7: =N7+3 -> 10 | P7: =O7+3 -> 13 | Q7: =P7+3 -> 16 | R7: =Q7+3 -> 19 | S7: =R7+3 -> 22
A8: C 작업구역 | B8: 토 공 사 | S8: 잔 손 보 기
B11: 철 거 공 사
B14: 우 수 공 사
B17: 포 장 공 사
B20: 구 조 물 공 사
B23: 부 대 공 사

Sheet 4.품질관리
B1: 4. 품질관리계획서
B3: 공사명 | C3: : | D3: =공사정보_출력X!C2 -> (예시) OO부대 시설물 보수공사
B4: 공사금액 | C4: : | D4: ="일금 "&numberstring(공사정보_출력X!C9,1)&"원정 ("&DOLLAR(공사정보_출력X!C9,0)&") " -> #NAME?
B5: 시공사 | C5: : | D5: =공사정보_출력X!C6 -> 주식회사 가상건설
B6: 착공년월일 | C6: : | D6: =공사정보_출력X!C11 -> 46029
B7: 준공(예정)년월일 | C7: : | D7: =공사정보_출력X!C12 -> 46073
B12: 건설기술관리법 시행령 제 41조의 제2항의 규정에 의하여 품질관리계획서를 제출합니다.
B17: 붙임 : | C17: 1. 품질관리계획 1부. 끝.
B20: =공사정보_출력X!C5 -> 46035
D23: 작성자 | E23: : | F23: =공사정보_출력X!E6 -> OO도 OO시 OO구 OO로 00 (OO동) OOO호
D24: 승인 | E24: : | F24: ="현장대리인 "&공사정보_출력X!C13&" (인)" -> 현장대리인 홍길동 (인)
D25: 확인 | E25: : | F25: 감독관 (인)
B27: =공사정보_출력X!C8 -> OO부대

Sheet 4-1.품질관리
B2: 4. 품질관리계획
B4: 4-1 공사개요
C6: 구분 | G6: 내용
C8: 공사명 | G8: =공사정보_출력X!C2 -> (예시) OO부대 시설물 보수공사
C9: 대지위치 | G9: =공사정보_출력X!C4 -> OO도 OO시 OO구
C10: 공사기간 | G10: =공사정보_출력X!C11 -> 46029 | P10: ~ | Q10: =공사정보_출력X!C12 -> 46073
C11: 공사내용 | G11: =공사정보_출력X!C3 -> 종합공사
B14: 4-2 품질관리 조직도
G16: 발 주 처 | Q16: 시 공 사
G17: =공사정보_출력X!C8 -> OO부대 | Q17: =공사정보_출력X!C6 -> 주식회사 가상건설
G18: =공사정보_출력X!D8 -> 031-000-0001 | Q18: =공사정보_출력X!D6 -> 031-000-0000
K21: 현장대리인
K22: =공사정보_출력X!C13 -> 홍길동
K23: =공사정보_출력X!E13 -> 010-1234-5678
K26: 품질관리자
K27: =공사정보_출력X!C13 -> 홍길동
K28: =공사정보_출력X!E13 -> 010-1234-5678
B40: 4-3 품질시험계획
C41: 1) 설계 또는 시공을 위하여 필요한 재료의 선정을 위한 시험
C42: 2) 사용하는 재료의 품질 확보에 관한 관계법규와 그에 따른 관계 규정이 적합하게 이루어지고
C43: 있는지 여부에 대한시험
C44: 3) 품질 확보 여부를 확인하기 위한 관리시험과 검사가 적정하게 실시 되었는지 여부에 대한 시험
B46: 4-4 시험기구 배치 계획
C47: 1) 필요시 시험 및 검사는 외부 전문기관에 의뢰한다.
C48: 2) 현장에 반입되는 자재는 육안검사를 우선으로 한다.
B50: 4-5 검사 및 시험 관리
B52: 1) 일반사항
C53: 품질관리는 설계도면과 시방서에 명시된 사용자재에 관한 품질관리(품질시험 및 검사)와
C54: 시공상태에 요구된 규격관리(시공관리)에 의하여 이루어져야 한다. 따라서 시공시 재료의 검사 및
C55: 시험, 시공중의 검사, 시공후의 검사 및 시험 등으로 품질관리를 수행하여야 한다.
C56: 본 공사는 구조물 보수공사로 공사 완료시에는 구조물 특성상 코아채취 등에 의한 재료의
C57: 품질검사가 곤란하므로 보수공사를 효과적으로 수행하기 위해서는 시공 중 단계별 시공관리 및
C58: 검사가 중요하다
B60: 2) 품질관리 요령
C61: 가. 재료의 검사 및 시험
D62: 1) 재료 반입시 종류・규격・반입량・제조업자명・제조년월일・저장유효기간・성능에
D63: 관련한 시험성적표(국공립품질시험 관련기관, 정부공인 품질시험 전문기관의 발행에 의한 것)를
D64: 명시하고, 감독관의 검수・승인을 받는다.
D65: 2) 감독관은 시방서 등에 기재된 품명 및 수량 등을 확인하고 품질시험을 실시한다.
D66: 3) 시공중의 재료검사 및 시험은 시공 전의 재료와 시공 중의 재료가 상이함이 있을 때 감독관의
...

Sheet 5. 안전관리
B1: 5. 안전관리계획서
B3: 공사명 | C3: : | D3: =공사정보_출력X!C2 -> (예시) OO부대 시설물 보수공사
B4: 공사금액 | C4: : | D4: ="일금 "&numberstring(공사정보_출력X!C9,1)&"원정 ("&DOLLAR(공사정보_출력X!C9,0)&") " -> #NAME?
B5: 시공사 | C5: : | D5: =공사정보_출력X!C6 -> 주식회사 가상건설
B6: 착공년월일 | C6: : | D6: =공사정보_출력X!C11 -> 46029
B7: 준공(예정)년월일 | C7: : | D7: =공사정보_출력X!C12 -> 46073
B12: 건설기술관리법 시행령 제 46조의 제2항의 규정에 의하여 안전관리계획서를 제출합니다.
B17: 붙임 : | C17: 1. 안전관리계획서 1부. 끝.
B20: =공사정보_출력X!C5 -> 46035
D23: 작성자 | E23: : | F23: =공사정보_출력X!E6 -> OO도 OO시 OO구 OO로 00 (OO동) OOO호
D24: 승인 | E24: : | F24: ="현장대리인 "&공사정보_출력X!C13&" (인)" -> 현장대리인 홍길동 (인)
D25: 확인 | E25: : | F25: 감독관 (인)
B27: =공사정보_출력X!C8 -> OO부대

Sheet 5-1.안전관리
B2: 5. 안전관리계획서
B4: 5-1 안전관리의 기본목표 및 방침
C6: 안전목표 | L6: 안전활동 | S6: 안전 평가 및 조치 | V6: 무재해 목표 달성
C7: 쾌적한 작업환경조성 | L7: 불안전한 행동 근절
C8: 근로자 안전보건 확보 | L8: 불안전시설 관리 철저
C9: 산업재해 예방 | L9: 안전교육과 점검 철저
B11: 5-2 안전관리의 조직도
F14: 발 주 처 | P14: 시 공 사
F15: =공사정보_출력X!C8 -> OO부대 | P15: =공사정보_출력X!C6 -> 주식회사 가상건설 | AB15: `
F16: =공사정보_출력X!D8 -> 031-000-0001 | P16: =공사정보_출력X!D6 -> 031-000-0000
J19: 현장대리인
J20: =공사정보_출력X!C13 -> 홍길동
J21: =공사정보_출력X!E13 -> 010-1234-5678
J24: 안전관리자
J25: =공사정보_출력X!C13 -> 홍길동
J26: =공사정보_출력X!E13 -> 010-1234-5678
B39: 5-3. 안전관리 항목
D40: 구 분 | K40: 내 용
D41: 1. 안전 관련 서류 비치 | K41: 안전관련 책자
D42: 2. 안 전 교 육 | K42: 소장교육 : 주간단위 / 반장교육 : 작업전 매일
D43: 3. 안전 장구 착용 | K43: 안전모 및 개인안전구 착용
D44: 4. 안전망,휀스 설치 | K44: 현장 여건에 따라 설치
D45: 5. 기 타 | K45: 위험부위 수시 점검
B47: 5-4. 안전점검계획
C48: 1) 목 적
C49: 현장의 안전관리 상태를 수시로 점검하여 작업환경의 불안전한 상태와 근로자의 불안전한 행동
C50: 으로부터 발생할 수 있는 모든 잠재적인 사고요인을 사전에 제거하여 인명및 재산을 보호하는데
C51: 목적이 있다.
D52: 가. 안전관리 조직구성 및 안전관리 활동의 적극적인 참여
D53: 나. 쾌적한 작업환경 및 안전시설의 개선
D54: 다. 근로자의 정신적 자세 확립
C55: 2) 안전점검대상
D56: 가. 안전관리 조직구성 및 안전관리 활동상태
D57: 나. 작업장의 정리정돈 및 불안전한 작업실시
D58: 다. 자재, 설비, 장비 및 차량운행의 점검 및 감독
D59: 라. 위험물 취급 및 방화관리 상태
D60: 마. 근로자들의 작업자세 확립과 반복적인 안전교육 실시상태
D61: 바. 각종 안전보호용구 착용 및 기타 안전에 관한사항
C62: 3) 안전점검 종류 및 내용
D63: 가. 현장 자체점검
...

Sheet 5-2.안전관리비사용계획서
C4: 총괄 산업안전 보건관리비 사용계획서
C6: 공 사 명 | G6: =공사정보_출력X!C2 -> (예시) OO부대 시설물 보수공사
C7: 시공사 | G7: =공사정보_출력X!C6 -> 주식회사 가상건설 | P7: 대표자 | T7: =공사정보_출력X!C7 -> 홍길동
C8: 소 재 지 | G8: =공사정보_출력X!E6 -> OO도 OO시 OO구 OO로 00 (OO동) OOO호
C9: 공사기간 | H9: =공사정보_출력X!C11 -> 46029 | N9: ~ | O9: =공사정보_출력X!C12 -> 46073
C10: 발주자 | G10: =공사정보_출력X!C8 -> OO부대 | P10: 공사금액 | T10: =공사정보_출력X!C9 -> 150000000
C11: 계상된 안전관리비 | G11: 3000000 | P11: 누계공정율
C12: 사 용 금 액
C13: 항 목 | P13: 사 용 금 액 | W13: 비고
C14: 1. 안전담당자 인건비(수당)및 안전보조원 인건비 | P14: =P41 -> 320000
C15: 2. 안전시설비등 | P15: =P46 -> 430000
C16: 3. 개인보호구 및 안전장비구입비등 | P16: =P54 -> 2236000
C17: 4. 안전진단비등 | P17: =P57 -> 0
C18: 5. 안전보건교육비 및 행사비등 | P18: =P60 -> 100000
C19: 6. 근로자건강진단비등 | P19: =P64 -> 160000
C20: 계 | P20: =SUM(P14:X19) -> 3246000
C24: 건설공사 산업안전 보건관리비 계상 및 사용기준 제10조 제1항의 규정에 의하여 위와 같이 사용 계획서를 제출합니다.
B25: =공사정보_출력X!C5 -> 46035
I28: 주소 | L28: : | N28: =공사정보_출력X!E6 -> OO도 OO시 OO구 OO로 00 (OO동) OOO호
I29: 상 호 | L29: : | N29: =공사정보_출력X!C6 -> 주식회사 가상건설
I30: 대표이사 | L30: : | N30: =공사정보_출력X!C7 -> 홍길동 | R30: (인)
B36: * 항목별 사용 계획서
B38: 항 목 | K38: 사 용 내 역 | P38: 단 가 | T38: 수 량 | V38: 금 액 | Z38: 비 고
B39: 1. 안전보건관계자 인건비 및 각종업무수당 | K39: 신호수 | P39: 160000 | T39: 2 | V39: =P39*T39 -> 320000
V40: =T40*P40 -> 0
B41: 소 계 | P41: =SUM(V39) -> 320000
B42: 2. 안전시설비 | K42: 소화기 | P42: 55000 | T42: 6 | V42: =T42*P42 -> 330000 | AU42: 10 | AW42: 250000
K43: 신호봉 | P43: 55000 | T43: 1 | V43: =T43*P43 -> 55000 | AU43: 5 | AW43: 250000
K44: 신호수조끼 | P44: 45000 | T44: 1 | V44: =T44*P44 -> 45000 | AU44: 5 | AW44: 250000
AU45: 3 | AW45: 450000
B46: 소 계 | P46: =SUM(V42:Y45) -> 430000
B47: 3. 개인보호구 및 안전장비구입비 | K47: 안 전 모 | P47: 10000 | T47: 20 | V47: =T47*P47 -> 200000 | AU47: 100 | AW47: 800000
K48: 안 전 화 | P48: 78000 | T48: 20 | V48: =T48*P48 -> 1560000 | AU48: 100 | AW48: 5000000
K49: 안전벨트 | P49: 50000 | T49: 5 | V49: =T49*P49 -> 250000 | AU49: 50 | AW49: 2400000
K50: 보안경 | P50: 9500 | T50: 20 | V50: =T50*P50 -> 190000 | AU50: 100 | AW50: 200000
K51: 방진마스크 | P51: 12000 | T51: 3 | V51: =T51*P51 -> 36000 | AU51: 100 | AW51: 200000
K52: 불티방지막 | T52: 2 | V52: =T52*P52 -> 0 | AU52: 100 | AW52: 2800000
AU53: 500 | AW53: 900000
B54: 소 계 | P54: =SUM(V47:Y53) -> 2236000
B55: 4. 안전진단비
...

Sheet 6. 환경관리
B1: 6. 환경관리계획서
B3: 공사명 | C3: : | D3: =공사정보_출력X!C2 -> (예시) OO부대 시설물 보수공사
B4: 공사금액 | C4: : | D4: ="일금 "&numberstring(공사정보_출력X!C9,1)&"원정 ("&DOLLAR(공사정보_출력X!C9,0)&") " -> #NAME?
B5: 시공사 | C5: : | D5: =공사정보_출력X!C6 -> 주식회사 가상건설
B6: 착공년월일 | C6: : | D6: =공사정보_출력X!C11 -> 46029
B7: 준공(예정)년월일 | C7: : | D7: =공사정보_출력X!C12 -> 46073
B12: 건설기술관리법 시행령 제 46조의 제8항의 규정에 의하여 안전관리계획서를 제출합니다.
B17: 붙임 : | C17: 1. 환경관리계획서 1부. 끝.
B20: =공사정보_출력X!C5 -> 46035
D23: 작성자 | E23: : | F23: =공사정보_출력X!E6 -> OO도 OO시 OO구 OO로 00 (OO동) OOO호
D24: 승인 | E24: : | F24: ="현장대리인 "&공사정보_출력X!C13&" (인)" -> 현장대리인 홍길동 (인)
D25: 확인 | E25: : | F25: 감독관 (인)
B27: =공사정보_출력X!C8 -> OO부대

Sheet 6-1. 환경관리
B2: 6. 환경보전계획
B4: 6-1 환경관리의 개요
C5: 본 계획서는 환경오염으로 인한 피해를 예방하여 주변지역 주민이 건강하고, 쾌적한 환경에서 생활할
C6: 수 있도록 자연환경 및 생활환경을 적정하게 관리 보전할 수 있는 시공으로 환경대책과 자연보호에
C7: 관한 일반적인 사항을 규정한다.
C8: 1) 관계법령 및 관리대상
D9: 법령 | J9: 주요 관리대상
D10: 소음진동관리법 | J10: 장비의 작업, 이동, 발파 등에 따른 소음 및 진동제어
D11: 폐기물관리법 | J11: 건설폐기물 처리의 적법처리
D12: 대기환경 보존법 | J12: 비산먼지 발생 저하
C13: 2) 현장 환경 목표
D14: ① 환경법규 준수, 쾌적한 작업장 조성
D15: ② 비산먼지 발생 최소화
D16: ③ 대외 민원 발생 최소화
D17: ④ 소음, 진동, 수질관리
B19: 6-2 환경관리조직도
G21: 발 주 처 | Q21: 시 공 사
G22: =공사정보_출력X!C8 -> OO부대 | Q22: =공사정보_출력X!C6 -> 주식회사 가상건설
G23: =공사정보_출력X!D8 -> 031-000-0001 | Q23: =공사정보_출력X!D6 -> 031-000-0000
K25: 현장대리인
K26: =공사정보_출력X!C13 -> 홍길동
K27: =공사정보_출력X!E13 -> 010-1234-5678
K29: 1. 환경사항 법적기준 준수
K30: 2. 현장점검, 환경개선 지시
K31: 3. 업무계획 독려
K32: 4. 환경 위반자 조치
K35: 환경관리자
K36: =공사정보_출력X!C13 -> 홍길동
K38: 현장내 환경관련 위반자 점검보고
K39: 및 확인감독
K40: 오염원의 지속적인 조사, 분석
K41: 대책수립 및 기록, 유지관리
B45: 6-3 환경점검계획
D47: 순 | E47: 구 분 | H47: 회 수 | L47: 환경교육의 내용 | W47: 비 고
D48: 1 | E48: 정기교육 | H48: 매월 1회 이상 | L48: 환경조직활동, 작업환경, 근로자작업자세등 전반적인 환경보전상태 확인
D49: 2 | E49: 수시교육 | H49: 수 시 | L49: 비산, 분진발생 및 예상지역에 대한 작업상태 확인
D50: 3 | E50: 특별교육 | H50: 점검사유 발생시 | L50: 천재지변, 작업 재개시등으로 작업시설 및 여건등의 안전이상 유무 점검
D51: 4 | E51: 작업전교육 | H51: 매일 작업전 | L51: 일상작업 개시전 작업환경시설, 장비등 작업여건 및 근로자의 작업방법 및 자세점검
D52: 5 | E52: 환경순찰 | H52: 매 일 | L52: 현장 전체의 이상유무에 대한 육안점검
B54: 6-4 분진, 소음 등 환경보전 계획
...

Sheet 6-2.환경보전비사용계획서
B3: 환경보전비 사용계획서
C5: 공 사 명 | G5: =공사정보_출력X!C2 -> (예시) OO부대 시설물 보수공사
C6: ='5-2.안전관리비사용계획서'!C7:F7 -> 시공사 | G6: =공사정보_출력X!C6 -> 주식회사 가상건설 | O6: 대표자 | S6: =공사정보_출력X!C7 -> 홍길동
C7: 소 재 지 | G7: =공사정보_출력X!E6 -> OO도 OO시 OO구 OO로 00 (OO동) OOO호
C8: 공사기간 | H8: =공사정보_출력X!C11 -> 46029 | N8: ~ | O8: =공사정보_출력X!C12 -> 46073
C9: 발주자 | G9: =공사정보_출력X!C8 -> OO부대 | O9: 공사금액 | S9: =공사정보_출력X!C9 -> 150000000
C10: 계상된 환경보전비 | G10: 800000 | O10: 누계공정율
C11: 사 용 금 액
C12: 항 목 | O12: 사 용 금 액 | V12: 비고
C13: 1. 환경보전시설 설치 및 운영비용 | O13: =O43 -> 840000
C14: 2. 환경계측비용 | O14: =O47 -> 0
C15: 3. 환경자료 및 홍보물 구입비용 | O15: =O51 -> 0
C16: 4. 환경관련 인건비용 | O16: =O55 -> 0
C17: 5. 환경교육 비용 | O17: =O58 -> 0
C22: 계 | O22: =SUM(O13:U21) -> 840000
C24: 위와 같이 환경보전비 사용계획을 제출합니다.
B26: ='5-2.안전관리비사용계획서'!B25:AA25 -> 46035
F29: 주소 | J29: : | K29: =공사정보_출력X!E6 -> OO도 OO시 OO구 OO로 00 (OO동) OOO호
F30: 상호 | J30: : | K30: =공사정보_출력X!C6 -> 주식회사 가상건설
F31: 대표이사 | J31: : | K31: =공사정보_출력X!C7 -> 홍길동 | P31: (인)
B36: * 항목별 사용 계획서
B38: 항 목 | J38: 사 용 내 역 | O38: 단 가 | S38: 수 량 | U38: 금 액 | Y38: 비 고
B39: =C13 -> 1. 환경보전시설 설치 및 운영비용 | J39: 집진기 | O39: 300000 | S39: 1 | U39: =O39*S39 -> 300000
J40: 살수차 | O40: 180000 | S40: 3 | U40: =S40*O40 -> 540000
U42: 0
B43: 소 계 | O43: =SUM(U39:X41) -> 840000
B44: =C14 -> 2. 환경계측비용 | O44: 0 | S44: 0 | U44: =S44*O44 -> 0
U45: =S45*O45 -> 0
U46: =O46*S46 -> 0
B47: 소 계 | O47: =SUM(U44:X46) -> 0
B48: =C15 -> 3. 환경자료 및 홍보물 구입비용 | O48: 0 | S48: 0 | U48: =S48*O48 -> 0
U49: =S49*O49 -> 0
U50: =S50*O50 -> 0
B51: 소 계 | O51: =SUM(U48:X50) -> 0
B52: =C16 -> 4. 환경관련 인건비용 | O52: 0 | S52: 0 | U52: =S52*O52 -> 0
U53: =S53*O53 -> 0
U54: =S54*O54 -> 0
B55: 소 계 | O55: =SUM(U52:X54) -> 0
B56: =C17 -> 5. 환경교육 비용 | O56: 0 | S56: 0 | U56: =S56*O56 -> 0
U57: =S57*O57 -> 0
...

Sheet 7.장비,인원동원
B2: 7. 인력 및 장비투입계획서
B4: 7-1. 인력 투입
D6: 공 종 | I6: 투 입 예 정 인 원 | U6: 비고
I7: 인 원 | M7: 일 수 | Q7: 계
D8: 토공사 | I8: 6 | M8: 7 | Q8: =I8*M8 -> 42
D9: 철거공사 | I9: 5 | M9: 7 | Q9: =I9*M9 -> 35
D10: 우수공사 | I10: 4 | M10: 3 | Q10: =I10*M10 -> 12
D11: 포장공사 | I11: 10 | M11: 14 | Q11: =I11*M11 -> 140
D12: 구조물공사 | I12: 5 | M12: 3 | Q12: =I12*M12 -> 15
D13: 부대공사 | I13: 5 | M13: 7 | Q13: =I13*M13 -> 35
D14: 계 | Q14: =SUM(Q8:T11) -> 229
B16: 7-2. 장비투입계획서
D18: 공 종 | H18: 장비명 | L18: 투 입 예 정 | U18: 비고
L19: 수량 | O19: 일수 | R19: 계
D20: 백호 | H20: 07W | L20: 1 | O20: 10 | R20: =L20*O20 -> 10
D21: 롤러 | H21: 10 TON | L21: 1 | O21: 10 | R21: =L21*O21 -> 10
D22: 로우더 | H22: 0.57 ㎥ | L22: 1 | O22: 10 | R22: =L22*O22 -> 10
D23: 덤프 | H23: 15 TON | L23: 3 | O23: 5 | R23: =L23*O23 -> 15
D24: 크레인 | H24: 10 TON | L24: 1 | O24: 3 | R24: =L24*O24 -> 3
D25: 계 | R25: =SUM(R20:T24) -> 48
P31: =공사정보_출력X!C6 -> 주식회사 가상건설

Sheet 8.착공전 사진 표지
B4: 착공전 사진대지
A6: =표지!A11 -> (예시) OO부대 시설물 보수공사
A11: =표지!A22 -> 46035
C18: =표지!A30 -> 주식회사 가상건설

Sheet 8-1. 사진
A2: 사 진 대 지
F3: =공사정보_출력X!C2 -> (예시) OO부대 시설물 보수공사
A13: 내용 | C13: 현장전경(정면)
A23: 내용 | C23: 현장전경(배면)
A33: 내용 | C33: 현장전경(동측)
A43: 내용 | C43: 현장전경(서측)
A53: 내용
A63: 내용
A73: 내용
A83: 내용
A93: 내용
A103: 내용
A113: 내용
A123: 내용
A133: 내용
A143: 내용
A153: 내용
A163: 내용
... A223: 내용

Sheet 9. 계약서
B4: 도급계약서
A6: =표지!A11 -> (예시) OO부대 시설물 보수공사
A11: =표지!A22 -> 46035
C18: =표지!A30 -> 주식회사 가상건설

Sheet 10.직접시공계획서
A1: 건설공사의 직접시공계획서
A2: 공사명 | B2: =공사정보_출력X!C2 -> (예시) OO부대 시설물 보수공사
A3: ①공종 | B3: =공사정보_출력X!C3 -> 종합공사 | G3: 현장소재지 | I3: =공사정보_출력X!C4 -> OO도 OO시 OO구
A4: 발주자 | B4: 상호 | C4: =공사정보_출력X!C8 -> OO부대 | I4: ■ 공공기관 □ 민간
B5: 담당자 | G5: 주소 | I5: =공사정보_출력X!C4 -> OO도 OO시 OO구
A6: 대표 | B6: 상호 | C6: =공사정보_출력X!C6 -> 주식회사 가상건설 | G6: 영업소소재지 | I6: =공사정보_출력X!E6 -> OO도 OO시 OO구 OO로 00 (OO동) OOO호
B7: 대표자 | C7: =공사정보_출력X!C7 -> 홍길동
A8: 도급(공동) | B8: 상호 | G8: 영업소소재지
B9: 대표자
A10: 도급방법 | B10: ■ 단독도급 □공동도급 (□공동이행방식 □분담이행방식 □주계약자관리방식)
A11: 계약성질 | B11: □ 장기계속공사 ■ 기타공사
A12: ②계약일 | B12: =공사정보_출력X!C10 -> 46029 | E12: ③ 착 공 일 | G12: =공사정보_출력X!C11 -> 46029 | I12: ④준공예정일 | K12: =공사정보_출력X!C12 -> 46073
A13: ⑤총 노무비 | B13: =I13 -> 104778032 | I13: =C40 -> 104778032
A14: 직 접 시 공 계 획
A15: 직접시공공종 | G15: 하도급(예정)공종
A16: ⑥세부공종 | C16: 금액 | G16: 세부공종 | J16: 금액
A17: ='10-1.직접시공내역서'!A5 -> (예시) OO부대 시설물 보수공사
A18: ='10-1.직접시공내역서'!A6 -> 전체 | C18: =SUM(C19:F24) -> 99707299
A19: ='10-1.직접시공내역서'!A7 -> 1.토 공 사 | C19: ='10-1.직접시공내역서'!K7 -> 3320130
A20: ='10-1.직접시공내역서'!A8 -> 2.철 거 공 사 | C20: ='10-1.직접시공내역서'!K8 -> 1622904
A21: ='10-1.직접시공내역서'!A9 -> 3.우 수 공 사 | C21: ='10-1.직접시공내역서'!K9 -> 5354574
A22: ='10-1.직접시공내역서'!A10 -> 4.포 장 공 사 | C22: ='10-1.직접시공내역서'!K10 -> 83626577
A23: ='10-1.직접시공내역서'!A11 -> 5.구 조 물 공 사 | C23: ='10-1.직접시공내역서'!K11 -> 1569854
A24: ='10-1.직접시공내역서'!A12 -> 6.부 대 공 사 | C24: ='10-1.직접시공내역서'!K12 -> 4213260
A25: ='10-1.직접시공내역서'!A13 -> 운 반 비 | C25: ='10-1.직접시공내역서'!K13 -> 900000
A26: ='10-1.직접시공내역서'!A14 -> 폐 기 물 처 리 비 | C26: ='10-1.직접시공내역서'!K14 -> 750000
A38: 소계 | C38: =SUM(C18) -> 99707299 | G38: 소계 | J38: =SUM(J16:L22) -> 0
A39: 간접노무비 | C39: 5070733 | G39: 간접노무비 | J39: =SUM(J17:L22) -> 0
A40: 직접시공 금액 합계 (직접시공 노무비) | C40: =C38+C39 -> 104778032 | G40: 합계 | J40: =SUM(J17:L22) -> 0
A42: 『건설산업기본법』 제 28조 2의 규정에 의하여 건설공사의 직접시공계획을 통보합니다.
A44: =공사정보_출력X!C5 -> 46035
C46: 대표 : | F46: =공사정보_출력X!C6 -> 주식회사 가상건설 | I46: =공사정보_출력X!C7 -> 홍길동 | K46: (인)
A48: =공사정보_출력X!C8 -> OO부대 | E48: 귀하
A50: 구비서류 | B50: 1. 직접시공 및 하도급할 공사량, 공사단가 및 공사금액(노무비)이 명시된 공사내역서
B51: 2. 예정공정표

Sheet 10-1.직접시공내역서
A1: 직 접 시 공 금 액 | Z1: 건축 | AA1: 기계 | AB1: 토목 | AD1: 총계
A2: ="공사명: "&공사정보_출력X!C2 -> 공사명: (예시) OO부대 시설물 보수공사 | Y2: 공사비 | Z2: 83514937
A3: 품 명 | B3: 규 격 | C3: 단위 | D3: 수량 | E3: 재 료 비 | G3: 노 무 비 | I3: 경 비 | K3: 도급액 | L3: 직접시공금액 | M3: 하도급 | O3: 하도급율 | P3: 비 고 | Q3: 공종코드 | R3: 변수 | S3: 상위공종 | T3: 공종구분 | U3: 공종레벨 | V3: 공종소계 | W3: 원가계산서 연결금액 | Y3: 총공사비 | Z3: 136361772 | AA3: 28648217 | AB3: 22999200 | AD3: =SUM(Z3:AB3) -> 188009189
E4: 단 가 | F4: 금 액 | G4: 단 가 | H4: 금 액 | I4: 단 가 | J4: 금 액 | K4: 금 액 | L4: 금 액 | M4: 단 가 | N4: 금 액 | Y4: 구분 | Z4: 공사비 | AA4: 구분 | AB4: 지반조성·포장 | AC4: 실내건축 | AD4: 금속창호·지붕건축물 | AE4: 도장·습식·방수·석공 | AF4: 조경식재 | AG4: 철근·콘크리트 | AH4: 구조물해체·비계 | AI4: 상·하수도 | AJ4: 철강구조물 | AK4: 기계가스설비공사업 | AL4: 가스난방 | AM4: 시설물유지 | AN4: 총계
A5: =공사정보_출력X!C2 -> (예시) OO부대 시설물 보수공사 | D5: 1 | E5: =E6 -> 63030677 | F5: =E5*D5 -> 63030677 | G5: =G6 -> 30731719 | H5: =G5*D5 -> 30731719 | I5: =I6 -> 5944903 | J5: =I5*D5 -> 5944903 | K5: =E5+G5+I5 -> 99707299 | L5: =F5+H5+J5 -> 99707299 | Q5: 01 | U5: 1 | Y5: =Z3/Z2 -> 1.632783 | Z5: =SUM(Z6:Z129) -> #REF! | AA5: 공사비 | AB5: =AB3 -> 22999200 | AC5: =SUMIF($Y$6:$Z$126,AC4,$Z$6:$Z$126) -> #REF! | AD5: =SUMIF($Y$6:$Z$126,AD4,$Z$6:$Z$126) -> 0 | AE5: =SUMIF($Y$6:$Z$126,AE4,$Z$6:$Z$126) -> #REF! | AF5: =SUMIF($Y$6:$Z$126,AF4,$Z$6:$Z$126) -> 0 | AG5: =SUMIF($Y$6:$Z$126,AG4,$Z$6:$Z$126) -> #REF! | AH5: =SUMIF($Y$6:$Z$126,AH4,$Z$6:$Z$126) -> 0 | AI5: =SUMIF($Y$6:$Z$126,AI4,$Z$6:$Z$126) -> 0 | AJ5: =SUMIF($Y$6:$Z$126,AJ4,$Z$6:$Z$126) -> 0 | AK5: =AA3 -> 28648217 | AL5: =SUMIF($Y$6:$Z$126,AL4,$Z$6:$Z$126) -> 0 | AM5: =SUMIF($Y$6:$Z$126,AM4,$Z$6:$Z$126) -> 0 | AN5: =SUM(AB5:AM5) -> #REF!
A6: 전체 | D6: 1 | E6: =F7+F8+F9+F10+F11+F12 -> 63030677 | F6: =E6*D6 -> 63030677 | G6: =H7+H8+H9+H10+H11+H12 -> 30731719 | H6: =G6*D6 -> 30731719 | I6: =J7+J8+J9+J10+J11+J12 -> 5944903 | J6: =I6*D6 -> 5944903 | K6: =E6+G6+I6 -> 99707299 | L6: =F6+H6+J6 -> 99707299 | Q6: 01010101 | S6: 010101 | U6: 4 | AA6: 면허필요여부 1500만원이상 | AB6: =IF(15000000<AB5,"O","X") -> O | AC6: =IF(15000000<AC5,"O","X") -> #REF! | AD6: =IF(15000000<AD5,"O","X") -> X | AE6: =IF(15000000<AE5,"O","X") -> #REF! | AF6: =IF(15000000<AF5,"O","X") -> X | AG6: =IF(15000000<AG5,"O","X") -> #REF! | AH6: =IF(15000000<AH5,"O","X") -> X | AI6: =IF(15000000<AI5,"O","X") -> X | ... AM6: =IF(15000000<AM5,"O","X") -> X
A7: 1.토 공 사 | D7: 1 | E7: 1036013 | F7: =E7*D7 -> 1036013 | G7: 1808354 | H7: =G7*D7 -> 1808354 | I7: 475763 | J7: =I7*D7 -> 475763 | K7: =E7+G7+I7 -> 3320130 | L7: =F7+H7+J7 -> 3320130 | Q7: 0101010101 | S7: 01010101 | U7: 5 | Y7: =AC4 -> 실내건축 | Z7: =#REF!*$Y$5 -> #REF!
A8: 2.철 거 공 사 | D8: 1 | E8: 114769 | F8: =E8*D8 -> 114769 | G8: 1309941 | H8: =G8*D8 -> 1309941 | I8: 198194 | J8: =I8*D8 -> 198194 | K8: =E8+G8+I8 -> 1622904 | L8: =F8+H8+J8 -> 1622904 | Q8: 0101010102 | S8: 01010101 | U8: 5 | Y8: =AG4 -> 철근·콘크리트 | Z8: =#REF!*$Y$5 -> #REF!
A9: 3.우 수 공 사 | D9: 1 | E9: 3514058 | F9: =E9*D9 -> 3514058 | G9: 1707261 | H9: =G9*D9 -> 1707261 | I9: 133255 | J9: =I9*D9 -> 133255 | K9: =E9+G9+I9 -> 5354574 | L9: =F9+H9+J9 -> 5354574 | Q9: 0101010103 | S9: 01010101 | U9: 5 | Y9: =AE4 -> 도장·습식·방수·석공 | Z9: =#REF!*$Y$5 -> #REF!
A10: 4.포 장 공 사 | D10: 1 | E10: 57955507 | F10: =E10*D10 -> 57955507 | G10: 23899331 | H10: =G10*D10 -> 23899331 | I10: 1771739 | J10: =I10*D10 -> 1771739 | K10: =E10+G10+I10 -> 83626577 | L10: =F10+H10+J10 -> 83626577 | Q10: 0101010104 | S10: 01010101 | U10: 5 | Y10: =AE4 -> 도장·습식·방수·석공 | Z10: =#REF!*$Y$5 -> #REF!
A11: 5.구 조 물 공 사 | D11: 1 | E11: 308126 | F11: =E11*D11 -> 308126 | G11: 1140906 | H11: =G11*D11 -> 1140906 | I11: 120822 | J11: =I11*D11 -> 120822 | K11: =E11+G11+I11 -> 1569854 | L11: =F11+H11+J11 -> 1569854 | Q11: 0101010105 | S11: 01010101 | U11: 5 | Y11: =AC4 -> 실내건축 | Z11: =#REF!*$Y$5 -> #REF!
A12: 6.부 대 공 사 | D12: 1 | E12: 102204 | F12: =E12*D12 -> 102204 | G12: 865926 | H12: =G12*D12 -> 865926 | I12: 3245130 | J12: =I12*D12 -> 3245130 | K12: =E12+G12+I12 -> 4213260 | L12: =F12+H12+J12 -> 4213260 | Q12: 0101010106 | S12: 01010101 | U12: 5 | Y12: =AE4 -> 도장·습식·방수·석공 | Z12: =#REF!*$Y$5 -> #REF!
A13: 운 반 비 | D13: 1 | E13: 500000 | F13: =E13*D13 -> 500000 | G13: 300000 | H13: =G13*D13 -> 300000 | I13: 100000 | J13: =I13*D13 -> 100000 | K13: =E13+G13+I13 -> 900000 | L13: =F13+H13+J13 -> 900000 | Q13: 0102 | T13: 7 | U13: 2 | W13: =#REF!*1 -> #REF!
A14: 폐 기 물 처 리 비 | D14: 1 | E14: 200000 | F14: =E14*D14 -> 200000 | G14: 150000 | H14: =G14*D14 -> 150000 | I14: 400000 | J14: =I14*D14 -> 400000 | K14: =E14+G14+I14 -> 750000 | L14: =F14+H14+J14 -> 750000 | Q14: 0103 | T14: 7 | U14: 2 | W14: =#REF!*1 -> #REF!
A17: [ 합 계 ] | F17: =F5 -> 63030677 | H17: =H5 -> 30731719 | J17: =J5 -> 5944903 | K17: =K5 -> 99707299 | L17: =L5 -> 99707299

Sheet 현장기구조직표
C3: 현장기구조직표
E9: 계약자 | O9: 시 공 사
E10: =공사정보_출력X!C8 -> OO부대 | O10: =공사정보_출력X!C6 -> 주식회사 가상건설
E11: =공사정보_출력X!D8 -> 031-000-0001 | O11: =공사정보_출력X!D6 -> 031-000-0000
I16: 현장대리인
I17: =공사정보_출력X!C13 -> 홍길동
I18: =공사정보_출력X!E13 -> 010-1234-5678

Sheet Sheet1
